Workbook

Sheet Leg
B2: LEGEND
B4: WORKSHEETS
B5: RES | C5: RESULTS
B6: 1 | C6: PRODUCTION PHASE
B7: 1 PRD | C7: production
B8: 2 | C8: CONSTRUCTION PHASE
B9: 2 CUT | C9: cut existing terrain
B10: 2 FILL | C10: fill existing terrain
B11: 2 SBGR | C11: subgrade layer preparation
B12: 2 SBBS | C12: subbase layer creation
B13: 2 BASE | C13: base layer creation
B14: 2 BIND | C14: binder layer creation
B15: 2 WEAR | C15: wearing layer creation
B16: 3 | C16: USE PHASE
B17: 3 ROLL | C17: roughness rolling resistance
B18: 3 MNTN | C18: maintenance operations
B19: 3 ALB | C19: albedo
B20: 3 LGT | C20: lighting
B22: each worksheet assesses CO2 emissions
B24: COLORS
C25: data to fill manually
C26: warning
C27: cells for the inputs
C28: cells for the CO2 outputs

Sheet RES
B2: TOTAL CO2 EMISSIONS (t)
B4: 1 | C4: PRODUCTION PHASE
B5: 1 PRD | C5: ='1 PRD'!F28 -> 141.0894
B7: 2 | C7: CONSTRUCTION PHASE
B8: 2 CUT | C8: ='2 CUT'!F158 -> 65.661303
B9: 2 FILL | C9: ='2 FILL'!F161 -> 36.758731
B10: 2 SBGR | C10: ='2 SBGR'!F74 -> 13.256617
B11: 2 SBBS | C11: ='2 SBBS'!F107 -> 38.875817
B12: 2 BASE | C12: ='2 BASE'!F107 -> 15.294389
B13: 2 BIND | C13: ='2 BIND'!F124 -> 2.1555969
B14: 2 WEAR | C14: ='2 WEAR'!F123 -> 1.7466642
C15: =SUM(C8:E14) -> 173.74912
B17: 3 | C17: USE PHASE
B18: MNTN | C18: ='3 MNTN'!F146 -> 16.918862
B19: LGT | C19: ='3 LGT'!F22 -> 357.7
B20: ALB | C20: ='3 ALB'!F22 -> 20975.854
B21: ROLL | C21: ='3 ROLL'!F58 -> 4875521.7
C22: =SUM(C18:E21) -> 4896872.2

Sheet 1 PRD
B2: MATERIAL QUANTITY (from CONSTRUCTION phase)
B4: wearing layer type | E4: (/) | F4: HMA
B5: emission equivalent for production | E5: (kg CO2 equiv./kg) | F5: =IF(F4=prms!$AR$5,prms!$AS$5,IF('1 PRD'!F4=prms!$AR$6,prms!$AS$6,IF('1 PRD'!F4=prms!$AR$7,prms!$AS$7,IF('1 PRD'!F4=prms!$AR$8,prms!$AS$8,IF('1 PRD'!F4=prms!$AR$9,prms!$AS$9,1))))) -> 0.0238
B6: wearing layer material mass | E6: (kg) | F6: ='2 WEAR'!$F$11*'2 WEAR'!$F$14 -> 1408000
B8: wearing layer type | E8: (/) | F8: HMA
B9: emission equivalent for production | E9: (kg CO2 equiv./kg) | F9: =IF(F8=prms!$AR$5,prms!$AS$5,IF('1 PRD'!F8=prms!$AR$6,prms!$AS$6,IF('1 PRD'!F8=prms!$AR$7,prms!$AS$7,IF('1 PRD'!F8=prms!$AR$8,prms!$AS$8,IF('1 PRD'!F8=prms!$AR$9,prms!$AS$9,1))))) -> 0.0238
B10: binder layer material mass | E10: (kg) | F10: ='2 BIND'!$F$11*'2 BIND'!$F$14 -> 1760000
B12: base layer type | E12: (/) | F12: gravel
B13: emission equivalent for production | E13: (kg CO2 equiv./kg) | F13: =IF(F12=prms!$AR$5,prms!$AS$5,IF('1 PRD'!F12=prms!$AR$6,prms!$AS$6,IF('1 PRD'!F12=prms!$AR$7,prms!$AS$7,IF('1 PRD'!F12=prms!$AR$8,prms!$AS$8,IF('1 PRD'!F12=prms!$AR$9,prms!$AS$9,1))))) -> 0.0027
B14: base layer material mass | E14: (kg) | F14: ='2 BASE'!$F$11*'2 BASE'!$F$14 -> 9120000
B16: subbase layer type | E16: (/) | F16: gravel
B17: emission equivalent for production | E17: (kg CO2 equiv./kg) | F17: =IF(F16=prms!$AR$5,prms!$AS$5,IF('1 PRD'!F16=prms!$AR$6,prms!$AS$6,IF('1 PRD'!F16=prms!$AR$7,prms!$AS$7,IF('1 PRD'!F16=prms!$AR$8,prms!$AS$8,IF('1 PRD'!F16=prms!$AR$9,prms!$AS$9,1))))) -> 0.0027
B18: subbase layer material mass | E18: (kg) | F18: ='2 SBBS'!$F$11*'2 SBBS'!$F$14 -> 15210000
B20: EMISSIONS
B22: emission for producing wearing layer | D22: CO2, wearing | E22: (kg) | F22: =F5*F6 -> 33510.4
B23: emission for producing binder layer | D23: CO2, binder | E23: (kg) | F23: =F9*F10 -> 41888
B24: emission for producing base layer | D24: CO2, base | E24: (kg) | F24: =F13*F14 -> 24624
B25: emission for producing subbase layer | D25: CO2, subbase | E25: (kg) | F25: =F17*F18 -> 41067
B27: total carbon dioxide emission | D27: CO2 | E27: (kg) | F27: =SUM(F22:F25) -> 141089.4
E28: (t) | F28: =F27/1000 -> 141.0894

Sheet 2 CUT
B2: ROAD LENGTH
B4: road length | E4: (m) | F4: 1000
B6: NEED TO CUT?
B8: need to cut? | E8: (/) | F8: 1 | G8: "1" for use, "0" for no use
B10: CUT TERRAIN TYPE (up to 5 layers)
B12: layer 1 width | E12: (m) | F12: 20
B13: layer 1 height | E13: (m) | F13: 0.5
B14: layer 1 type | E14: (/) | F14: clay - dry
B15: density in bank | D15: ρb,1 | E15: (kg/m3) | F15: =IF( F14=prms!$B$5,prms!$C$5, IF(F14=prms!$B$6,prms!$C$6, IF(F14=prms!$B$7,prms!$C$7, IF(F14=prms!$B$8,prms!$C$8, IF(F14=prms!$B$9,prms!$C$9, IF(F14=prms!$B$10,prms!$C$10, IF(F14=prms!$B$11,prms!$C$11, IF(F14=prms!$B$12,prms!$C$12, IF(F14=prms!$B$13,prms!$C$13, IF(F14=prms!$B$14,prms!$C$14, IF(F14=prms!$B$15,prms!$C$15, IF(F14=prms!$B$16,prms!$C$16, IF(F14=prms!$B$17,prms!$C$17, IF(F14=prms!$B$18,prms!$C$18, IF(F14=prms!$B$19,prms!$C$19, IF(F14=prms!$B$20,prms!$C$20, IF(F14=prms!$B$21,prms!$C$21, IF(F14=prms!$B$22,prms!$C$22, IF(F14=prms!$B$23,prms!$C$23, IF(F14=prms!$B$24,prms!$C$24, IF(F14=prms!$B$25,prms!$C$25, IF(F14=prms!$B$26,prms!$C$26, IF(F14=prms!$B$27,prms!$C$27, IF(F14=prms!$B$28,prms!$C$28, IF(F14=prms!$B$29,prms!$C$29, ))))))))))))))))))))))))) -> 1840
B16: density loose | D16: ρl,1 | E16: (kg/m3) | F16: =IF( F14=prms!$B$5,prms!$D$5, IF(F14=prms!$B$6,prms!$D$6, IF(F14=prms!$B$7,prms!$D$7, IF(F14=prms!$B$8,prms!$D$8, IF(F14=prms!$B$9,prms!$D$9, IF(F14=prms!$B$10,prms!$D$10, IF(F14=prms!$B$11,prms!$D$11, IF(F14=prms!$B$12,prms!$D$12, IF(F14=prms!$B$13,prms!$D$13, IF(F14=prms!$B$14,prms!$D$14, IF(F14=prms!$B$15,prms!$D$15, IF(F14=prms!$B$16,prms!$D$16, IF(F14=prms!$B$17,prms!$D$17, IF(F14=prms!$B$18,prms!$D$18, IF(F14=prms!$B$19,prms!$D$19, IF(F14=prms!$B$20,prms!$D$20, IF(F14=prms!$B$21,prms!$D$21, IF(F14=prms!$B$22,prms!$D$22, IF(F14=prms!$B$23,prms!$D$23, IF(F14=prms!$B$24,prms!$D$24, IF(F14=prms!$B$25,prms!$D$25, IF(F14=prms!$B$26,prms!$D$26, IF(F14=prms!$B$27,prms!$D$27, IF(F14=prms!$B$28,prms!$D$28, IF(F14=prms!$B$29,prms!$D$29))))))))))))))))))))))))) -> 1480
B18: layer 2 width | E18: (m) | F18: 20
B19: layer 2 height | E19: (m) | F19: 0.5
B20: layer 2 type | E20: (/) | F20: clay - wet
B21: density in bank | D21: ρb,2 | E21: (kg/m3) | F21: =IF( F20=prms!$B$5,prms!$C$5, IF(F20=prms!$B$6,prms!$C$6, IF(F20=prms!$B$7,prms!$C$7, IF(F20=prms!$B$8,prms!$C$8, IF(F20=prms!$B$9,prms!$C$9, IF(F20=prms!$B$10,prms!$C$10, IF(F20=prms!$B$11,prms!$C$11, IF(F20=prms!$B$12,prms!$C$12, IF(F20=prms!$B$13,prms!$C$13, IF(F20=prms!$B$14,prms!$C$14, IF(F20=prms!$B$15,prms!$C$15, IF(F20=prms!$B$16,prms!$C$16, IF(F20=prms!$B$17,prms!$C$17, IF(F20=prms!$B$18,prms!$C$18, IF(F20=prms!$B$19,prms!$C$19, IF(F20=prms!$B$20,prms!$C$20, IF(F20=prms!$B$21,prms!$C$21, IF(F20=prms!$B$22,prms!$C$22, IF(F20=prms!$B$23,prms!$C$23, IF(F20=prms!$B$24,prms!$C$24, IF(F20=prms!$B$25,prms!$C$25, IF(F20=prms!$B$26,prms!$C$26, IF(F20=prms!$B$27,prms!$C$27, IF(F20=prms!$B$28,prms!$C$28, IF(F20=prms!$B$29,prms!$C$29, ))))))))))))))))))))))))) -> 2080
B22: density loose | D22: ρl,2 | E22: (kg/m3) | F22: =IF( F20=prms!$B$5,prms!$D$5, IF(F20=prms!$B$6,prms!$D$6, IF(F20=prms!$B$7,prms!$D$7, IF(F20=prms!$B$8,prms!$D$8, IF(F20=prms!$B$9,prms!$D$9, IF(F20=prms!$B$10,prms!$D$10, IF(F20=prms!$B$11,prms!$D$11, IF(F20=prms!$B$12,prms!$D$12, IF(F20=prms!$B$13,prms!$D$13, IF(F20=prms!$B$14,prms!$D$14, IF(F20=prms!$B$15,prms!$D$15, IF(F20=prms!$B$16,prms!$D$16, IF(F20=prms!$B$17,prms!$D$17, IF(F20=prms!$B$18,prms!$D$18, IF(F20=prms!$B$19,prms!$D$19, IF(F20=prms!$B$20,prms!$D$20, IF(F20=prms!$B$21,prms!$D$21, IF(F20=prms!$B$22,prms!$D$22, IF(F20=prms!$B$23,prms!$D$23, IF(F20=prms!$B$24,prms!$D$24, IF(F20=prms!$B$25,prms!$D$25, IF(F20=prms!$B$26,prms!$D$26, IF(F20=prms!$B$27,prms!$D$27, IF(F20=prms!$B$28,prms!$D$28, IF(F20=prms!$B$29,prms!$D$29))))))))))))))))))))))))) -> 1660
B24: layer 3 width | E24: (m) | F24: 20
B25: layer 3 height | E25: (m) | F25: 0.5
B26: layer 3 type | E26: (/) | F26: clay and gravel - dry
B27: density in bank | D27: ρb,3 | E27: (kg/m3) | F27: =IF( F26=prms!$B$5,prms!$C$5, IF(F26=prms!$B$6,prms!$C$6, IF(F26=prms!$B$7,prms!$C$7, IF(F26=prms!$B$8,prms!$C$8, IF(F26=prms!$B$9,prms!$C$9, IF(F26=prms!$B$10,prms!$C$10, IF(F26=prms!$B$11,prms!$C$11, IF(F26=prms!$B$12,prms!$C$12, IF(F26=prms!$B$13,prms!$C$13, IF(F26=prms!$B$14,prms!$C$14, IF(F26=prms!$B$15,prms!$C$15, IF(F26=prms!$B$16,prms!$C$16, IF(F26=prms!$B$17,prms!$C$17, IF(F26=prms!$B$18,prms!$C$18, IF(F26=prms!$B$19,prms!$C$19, IF(F26=prms!$B$20,prms!$C$20, IF(F26=prms!$B$21,prms!$C$21, IF(F26=prms!$B$22,prms!$C$22, IF(F26=prms!$B$23,prms!$C$23, IF(F26=prms!$B$24,prms!$C$24, IF(F26=prms!$B$25,prms!$C$25, IF(F26=prms!$B$26,prms!$C$26, IF(F26=prms!$B$27,prms!$C$27, IF(F26=prms!$B$28,prms!$C$28, IF(F26=prms!$B$29,prms!$C$29, ))))))))))))))))))))))))) -> 1660
B28: density loose | D28: ρl,3 | E28: (kg/m3) | F28: =IF( F26=prms!$B$5,prms!$D$5, IF(F26=prms!$B$6,prms!$D$6, IF(F26=prms!$B$7,prms!$D$7, IF(F26=prms!$B$8,prms!$D$8, IF(F26=prms!$B$9,prms!$D$9, IF(F26=prms!$B$10,prms!$D$10, IF(F26=prms!$B$11,prms!$D$11, IF(F26=prms!$B$12,prms!$D$12, IF(F26=prms!$B$13,prms!$D$13, IF(F26=prms!$B$14,prms!$D$14, IF(F26=prms!$B$15,prms!$D$15, IF(F26=prms!$B$16,prms!$D$16, IF(F26=prms!$B$17,prms!$D$17, IF(F26=prms!$B$18,prms!$D$18, IF(F26=prms!$B$19,prms!$D$19, IF(F26=prms!$B$20,prms!$D$20, IF(F26=prms!$B$21,prms!$D$21, IF(F26=prms!$B$22,prms!$D$22, IF(F26=prms!$B$23,prms!$D$23, IF(F26=prms!$B$24,prms!$D$24, IF(F26=prms!$B$25,prms!$D$25, IF(F26=prms!$B$26,prms!$D$26, IF(F26=prms!$B$27,prms!$D$27, IF(F26=prms!$B$28,prms!$D$28, IF(F26=prms!$B$29,prms!$D$29))))))))))))))))))))))))) -> 1420
B30: layer 4 width | E30: (m) | F30: 20
B31: layer 4 height | E31: (m) | F31: 0.5
B32: layer 4 type | E32: (/) | F32: clay and gravel - wet
B33: density in bank | D33: ρb,4 | E33: (kg/m3) | F33: =IF( F32=prms!$B$5,prms!$C$5, IF(F32=prms!$B$6,prms!$C$6, IF(F32=prms!$B$7,prms!$C$7, IF(F32=prms!$B$8,prms!$C$8, IF(F32=prms!$B$9,prms!$C$9, IF(F32=prms!$B$10,prms!$C$10, IF(F32=prms!$B$11,prms!$C$11, IF(F32=prms!$B$12,prms!$C$12, IF(F32=prms!$B$13,prms!$C$13, IF(F32=prms!$B$14,prms!$C$14, IF(F32=prms!$B$15,prms!$C$15, IF(F32=prms!$B$16,prms!$C$16, IF(F32=prms!$B$17,prms!$C$17, IF(F32=prms!$B$18,prms!$C$18, IF(F32=prms!$B$19,prms!$C$19, IF(F32=prms!$B$20,prms!$C$20, IF(F32=prms!$B$21,prms!$C$21, IF(F32=prms!$B$22,prms!$C$22, IF(F32=prms!$B$23,prms!$C$23, IF(F32=prms!$B$24,prms!$C$24, IF(F32=prms!$B$25,prms!$C$25, IF(F32=prms!$B$26,prms!$C$26, IF(F32=prms!$B$27,prms!$C$27, IF(F32=prms!$B$28,prms!$C$28, IF(F32=prms!$B$29,prms!$C$29, ))))))))))))))))))))))))) -> 1840
B34: density loose | D34: ρl,4 | E34: (kg/m3) | F34: =IF( F32=prms!$B$5,prms!$D$5, IF(F32=prms!$B$6,prms!$D$6, IF(F32=prms!$B$7,prms!$D$7, IF(F32=prms!$B$8,prms!$D$8, IF(F32=prms!$B$9,prms!$D$9, IF(F32=prms!$B$10,prms!$D$10, IF(F32=prms!$B$11,prms!$D$11, IF(F32=prms!$B$12,prms!$D$12, IF(F32=prms!$B$13,prms!$D$13, IF(F32=prms!$B$14,prms!$D$14, IF(F32=prms!$B$15,prms!$D$15, IF(F32=prms!$B$16,prms!$D$16, IF(F32=prms!$B$17,prms!$D$17, IF(F32=prms!$B$18,prms!$D$18, IF(F32=prms!$B$19,prms!$D$19, IF(F32=prms!$B$20,prms!$D$20, IF(F32=prms!$B$21,prms!$D$21, IF(F32=prms!$B$22,prms!$D$22, IF(F32=prms!$B$23,prms!$D$23, IF(F32=prms!$B$24,prms!$D$24, IF(F32=prms!$B$25,prms!$D$25, IF(F32=prms!$B$26,prms!$D$26, IF(F32=prms!$B$27,prms!$D$27, IF(F32=prms!$B$28,prms!$D$28, IF(F32=prms!$B$29,prms!$D$29))))))))))))))))))))))))) -> 1540
B36: layer 5 width | E36: (m) | F36: 20
B37: layer 5 height | E37: (m) | F37: 0.5
B38: layer 5 type | E38: (/) | F38: earth - dry packed
B39: density in bank | D39: ρb,5 | E39: (kg/m3) | F39: =IF( F38=prms!$B$5,prms!$C$5, IF(F38=prms!$B$6,prms!$C$6, IF(F38=prms!$B$7,prms!$C$7, IF(F38=prms!$B$8,prms!$C$8, IF(F38=prms!$B$9,prms!$C$9, IF(F38=prms!$B$10,prms!$C$10, IF(F38=prms!$B$11,prms!$C$11, IF(F38=prms!$B$12,prms!$C$12, IF(F38=prms!$B$13,prms!$C$13, IF(F38=prms!$B$14,prms!$C$14, IF(F38=prms!$B$15,prms!$C$15, IF(F38=prms!$B$16,prms!$C$16, IF(F38=prms!$B$17,prms!$C$17, IF(F38=prms!$B$18,prms!$C$18, IF(F38=prms!$B$19,prms!$C$19, IF(F38=prms!$B$20,prms!$C$20, IF(F38=prms!$B$21,prms!$C$21, IF(F38=prms!$B$22,prms!$C$22, IF(F38=prms!$B$23,prms!$C$23, IF(F38=prms!$B$24,prms!$C$24, IF(F38=prms!$B$25,prms!$C$25, IF(F38=prms!$B$26,prms!$C$26, IF(F38=prms!$B$27,prms!$C$27, IF(F38=prms!$B$28,prms!$C$28, IF(F38=prms!$B$29,prms!$C$29, ))))))))))))))))))))))))) -> 1900
B40: density loose | D40: ρl,5 | E40: (kg/m3) | F40: =IF( F38=prms!$B$5,prms!$D$5, IF(F38=prms!$B$6,prms!$D$6, IF(F38=prms!$B$7,prms!$D$7, IF(F38=prms!$B$8,prms!$D$8, IF(F38=prms!$B$9,prms!$D$9, IF(F38=prms!$B$10,prms!$D$10, IF(F38=prms!$B$11,prms!$D$11, IF(F38=prms!$B$12,prms!$D$12, IF(F38=prms!$B$13,prms!$D$13, IF(F38=prms!$B$14,prms!$D$14, IF(F38=prms!$B$15,prms!$D$15, IF(F38=prms!$B$16,prms!$D$16, IF(F38=prms!$B$17,prms!$D$17, IF(F38=prms!$B$18,prms!$D$18, IF(F38=prms!$B$19,prms!$D$19, IF(F38=prms!$B$20,prms!$D$20, IF(F38=prms!$B$21,prms!$D$21, IF(F38=prms!$B$22,prms!$D$22, IF(F38=prms!$B$23,prms!$D$23, IF(F38=prms!$B$24,prms!$D$24, IF(F38=prms!$B$25,prms!$D$25, IF(F38=prms!$B$26,prms!$D$26, IF(F38=prms!$B$27,prms!$D$27, IF(F38=prms!$B$28,prms!$D$28, IF(F38=prms!$B$29,prms!$D$29))))))))))))))))))))))))) -> 1510
B42: total cut volume | E42: (m3) | F42: =F4*(F12*F13+F18*F19+F24*F25+F30*F31+F36*F37) -> 50000
B44: EXCAVATORS FOR CUTTING (up to three types of excavator)
B46: excavator "A" | E46: (-) | F46: 1 | G46: "1" for use, "0" for no use
B47: excavator "A" type | E47: (/) | F47: mini tracked excavator
B48: power | E48: (kW) | F48: 20 | G48: inside this suggested range | I48: =IF($F$47=prms!F5,prms!G5,IF($F$47=prms!F6,prms!G6,IF('2 CUT'!$F$47=prms!F7,prms!G7,IF('2 CUT'!$F$47=prms!F8,prms!G8,IF('2 CUT'!$F$47=prms!F9,prms!G9,1))))) -> 6.8 - 48.5
B49: specific consumption | D49: SCex,A | E49: (kg / kW h) | F49: 0.25 | G49: 0.25 if characteristic curve is not available
B50: daily duration of excavator use | D50: Tex,A | E50: (min) | F50: 480
B51: specific weight of fuel | D51: ρex,A,fuel | E51: (kg/l) | F51: 0.85
B52: productivity | D52: Prex,A | E52: (h/m3) | F52: 0.01 | G52: inside this suggested range | I52: 0.007 - 0.012
B53: load factor 1 for layer 1 | D53: LFex,A,1,1 | E53: (-) | F53: =0.0339*EXP(0.0014*$F$15) -> 0.44559703
...

Sheet 2 FILL
B2: ROAD LENGTH
B4: road length | E4: (m) | F4: 1000
B6: NEED TO FILL?
B8: need to fill? | E8: (/) | F8: 1 | G8: "1" for use, "0" for no use
B10: FILL TERRAIN TYPE (up to 5 layers)
B12: layer 1 width | E12: (m) | F12: 20
B13: layer 1 height | E13: (m) | F13: 0.3
B14: layer 1 type | E14: (/) | F14: gravel - dry
B15: density in bank | D15: ρb,1 | E15: (kg/m3) | F15: =IF( F14=prms!$B$5,prms!$C$5, IF(F14=prms!$B$6,prms!$C$6, IF(F14=prms!$B$7,prms!$C$7, IF(F14=prms!$B$8,prms!$C$8, IF(F14=prms!$B$9,prms!$C$9, IF(F14=prms!$B$10,prms!$C$10, IF(F14=prms!$B$11,prms!$C$11, IF(F14=prms!$B$12,prms!$C$12, IF(F14=prms!$B$13,prms!$C$13, IF(F14=prms!$B$14,prms!$C$14, IF(F14=prms!$B$15,prms!$C$15, IF(F14=prms!$B$16,prms!$C$16, IF(F14=prms!$B$17,prms!$C$17, IF(F14=prms!$B$18,prms!$C$18, IF(F14=prms!$B$19,prms!$C$19, IF(F14=prms!$B$20,prms!$C$20, IF(F14=prms!$B$21,prms!$C$21, IF(F14=prms!$B$22,prms!$C$22, IF(F14=prms!$B$23,prms!$C$23, IF(F14=prms!$B$24,prms!$C$24, IF(F14=prms!$B$25,prms!$C$25, IF(F14=prms!$B$26,prms!$C$26, IF(F14=prms!$B$27,prms!$C$27, IF(F14=prms!$B$28,prms!$C$28, IF(F14=prms!$B$29,prms!$C$29, ))))))))))))))))))))))))) -> 1690
B16: density loose | D16: ρl,1 | E16: (kg/m3) | F16: =IF( F14=prms!$B$5,prms!$D$5, IF(F14=prms!$B$6,prms!$D$6, IF(F14=prms!$B$7,prms!$D$7, IF(F14=prms!$B$8,prms!$D$8, IF(F14=prms!$B$9,prms!$D$9, IF(F14=prms!$B$10,prms!$D$10, IF(F14=prms!$B$11,prms!$D$11, IF(F14=prms!$B$12,prms!$D$12, IF(F14=prms!$B$13,prms!$D$13, IF(F14=prms!$B$14,prms!$D$14, IF(F14=prms!$B$15,prms!$D$15, IF(F14=prms!$B$16,prms!$D$16, IF(F14=prms!$B$17,prms!$D$17, IF(F14=prms!$B$18,prms!$D$18, IF(F14=prms!$B$19,prms!$D$19, IF(F14=prms!$B$20,prms!$D$20, IF(F14=prms!$B$21,prms!$D$21, IF(F14=prms!$B$22,prms!$D$22, IF(F14=prms!$B$23,prms!$D$23, IF(F14=prms!$B$24,prms!$D$24, IF(F14=prms!$B$25,prms!$D$25, IF(F14=prms!$B$26,prms!$D$26, IF(F14=prms!$B$27,prms!$D$27, IF(F14=prms!$B$28,prms!$D$28, IF(F14=prms!$B$29,prms!$D$29))))))))))))))))))))))))) -> 1510
B18: layer 2 width | E18: (m) | F18: 20
B19: layer 2 height | E19: (m) | F19: 0.3
B20: layer 2 type | E20: (/) | F20: gravel - wet 6-50 mm
B21: density in bank | D21: ρb,2 | E21: (kg/m3) | F21: =IF( F20=prms!$B$5,prms!$C$5, IF(F20=prms!$B$6,prms!$C$6, IF(F20=prms!$B$7,prms!$C$7, IF(F20=prms!$B$8,prms!$C$8, IF(F20=prms!$B$9,prms!$C$9, IF(F20=prms!$B$10,prms!$C$10, IF(F20=prms!$B$11,prms!$C$11, IF(F20=prms!$B$12,prms!$C$12, IF(F20=prms!$B$13,prms!$C$13, IF(F20=prms!$B$14,prms!$C$14, IF(F20=prms!$B$15,prms!$C$15, IF(F20=prms!$B$16,prms!$C$16, IF(F20=prms!$B$17,prms!$C$17, IF(F20=prms!$B$18,prms!$C$18, IF(F20=prms!$B$19,prms!$C$19, IF(F20=prms!$B$20,prms!$C$20, IF(F20=prms!$B$21,prms!$C$21, IF(F20=prms!$B$22,prms!$C$22, IF(F20=prms!$B$23,prms!$C$23, IF(F20=prms!$B$24,prms!$C$24, IF(F20=prms!$B$25,prms!$C$25, IF(F20=prms!$B$26,prms!$C$26, IF(F20=prms!$B$27,prms!$C$27, IF(F20=prms!$B$28,prms!$C$28, IF(F20=prms!$B$29,prms!$C$29, ))))))))))))))))))))))))) -> 2260
B22: density loose | D22: ρl,2 | E22: (kg/m3) | F22: =IF( F20=prms!$B$5,prms!$D$5, IF(F20=prms!$B$6,prms!$D$6, IF(F20=prms!$B$7,prms!$D$7, IF(F20=prms!$B$8,prms!$D$8, IF(F20=prms!$B$9,prms!$D$9, IF(F20=prms!$B$10,prms!$D$10, IF(F20=prms!$B$11,prms!$D$11, IF(F20=prms!$B$12,prms!$D$12, IF(F20=prms!$B$13,prms!$D$13, IF(F20=prms!$B$14,prms!$D$14, IF(F20=prms!$B$15,prms!$D$15, IF(F20=prms!$B$16,prms!$D$16, IF(F20=prms!$B$17,prms!$D$17, IF(F20=prms!$B$18,prms!$D$18, IF(F20=prms!$B$19,prms!$D$19, IF(F20=prms!$B$20,prms!$D$20, IF(F20=prms!$B$21,prms!$D$21, IF(F20=prms!$B$22,prms!$D$22, IF(F20=prms!$B$23,prms!$D$23, IF(F20=prms!$B$24,prms!$D$24, IF(F20=prms!$B$25,prms!$D$25, IF(F20=prms!$B$26,prms!$D$26, IF(F20=prms!$B$27,prms!$D$27, IF(F20=prms!$B$28,prms!$D$28, IF(F20=prms!$B$29,prms!$D$29))))))))))))))))))))))))) -> 2020
B24: layer 3 width | E24: (m) | F24: 20
B25: layer 3 height | E25: (m) | F25: 0.3
B26: layer 3 type | E26: (/) | F26: rock 25% earth 75%
B27: density in bank | D27: ρb,3 | E27: (kg/m3) | F27: =IF( F26=prms!$B$5,prms!$C$5, IF(F26=prms!$B$6,prms!$C$6, IF(F26=prms!$B$7,prms!$C$7, IF(F26=prms!$B$8,prms!$C$8, IF(F26=prms!$B$9,prms!$C$9, IF(F26=prms!$B$10,prms!$C$10, IF(F26=prms!$B$11,prms!$C$11, IF(F26=prms!$B$12,prms!$C$12, IF(F26=prms!$B$13,prms!$C$13, IF(F26=prms!$B$14,prms!$C$14, IF(F26=prms!$B$15,prms!$C$15, IF(F26=prms!$B$16,prms!$C$16, IF(F26=prms!$B$17,prms!$C$17, IF(F26=prms!$B$18,prms!$C$18, IF(F26=prms!$B$19,prms!$C$19, IF(F26=prms!$B$20,prms!$C$20, IF(F26=prms!$B$21,prms!$C$21, IF(F26=prms!$B$22,prms!$C$22, IF(F26=prms!$B$23,prms!$C$23, IF(F26=prms!$B$24,prms!$C$24, IF(F26=prms!$B$25,prms!$C$25, IF(F26=prms!$B$26,prms!$C$26, IF(F26=prms!$B$27,prms!$C$27, IF(F26=prms!$B$28,prms!$C$28, IF(F26=prms!$B$29,prms!$C$29, ))))))))))))))))))))))))) -> 1960
B28: density loose | D28: ρl,3 | E28: (kg/m3) | F28: =IF( F26=prms!$B$5,prms!$D$5, IF(F26=prms!$B$6,prms!$D$6, IF(F26=prms!$B$7,prms!$D$7, IF(F26=prms!$B$8,prms!$D$8, IF(F26=prms!$B$9,prms!$D$9, IF(F26=prms!$B$10,prms!$D$10, IF(F26=prms!$B$11,prms!$D$11, IF(F26=prms!$B$12,prms!$D$12, IF(F26=prms!$B$13,prms!$D$13, IF(F26=prms!$B$14,prms!$D$14, IF(F26=prms!$B$15,prms!$D$15, IF(F26=prms!$B$16,prms!$D$16, IF(F26=prms!$B$17,prms!$D$17, IF(F26=prms!$B$18,prms!$D$18, IF(F26=prms!$B$19,prms!$D$19, IF(F26=prms!$B$20,prms!$D$20, IF(F26=prms!$B$21,prms!$D$21, IF(F26=prms!$B$22,prms!$D$22, IF(F26=prms!$B$23,prms!$D$23, IF(F26=prms!$B$24,prms!$D$24, IF(F26=prms!$B$25,prms!$D$25, IF(F26=prms!$B$26,prms!$D$26, IF(F26=prms!$B$27,prms!$D$27, IF(F26=prms!$B$28,prms!$D$28, IF(F26=prms!$B$29,prms!$D$29))))))))))))))))))))))))) -> 1570
B30: layer 4 width | E30: (m) | F30: 20
B31: layer 4 height | E31: (m) | F31: 0.3
B32: layer 4 type | E32: (/) | F32: rock 50% earth 50%
B33: density in bank | D33: ρb,4 | E33: (kg/m3) | F33: =IF( F32=prms!$B$5,prms!$C$5, IF(F32=prms!$B$6,prms!$C$6, IF(F32=prms!$B$7,prms!$C$7, IF(F32=prms!$B$8,prms!$C$8, IF(F32=prms!$B$9,prms!$C$9, IF(F32=prms!$B$10,prms!$C$10, IF(F32=prms!$B$11,prms!$C$11, IF(F32=prms!$B$12,prms!$C$12, IF(F32=prms!$B$13,prms!$C$13, IF(F32=prms!$B$14,prms!$C$14, IF(F32=prms!$B$15,prms!$C$15, IF(F32=prms!$B$16,prms!$C$16, IF(F32=prms!$B$17,prms!$C$17, IF(F32=prms!$B$18,prms!$C$18, IF(F32=prms!$B$19,prms!$C$19, IF(F32=prms!$B$20,prms!$C$20, IF(F32=prms!$B$21,prms!$C$21, IF(F32=prms!$B$22,prms!$C$22, IF(F32=prms!$B$23,prms!$C$23, IF(F32=prms!$B$24,prms!$C$24, IF(F32=prms!$B$25,prms!$C$25, IF(F32=prms!$B$26,prms!$C$26, IF(F32=prms!$B$27,prms!$C$27, IF(F32=prms!$B$28,prms!$C$28, IF(F32=prms!$B$29,prms!$C$29, ))))))))))))))))))))))))) -> 2280
B34: density loose | D34: ρl,4 | E34: (kg/m3) | F34: =IF( F32=prms!$B$5,prms!$D$5, IF(F32=prms!$B$6,prms!$D$6, IF(F32=prms!$B$7,prms!$D$7, IF(F32=prms!$B$8,prms!$D$8, IF(F32=prms!$B$9,prms!$D$9, IF(F32=prms!$B$10,prms!$D$10, IF(F32=prms!$B$11,prms!$D$11, IF(F32=prms!$B$12,prms!$D$12, IF(F32=prms!$B$13,prms!$D$13, IF(F32=prms!$B$14,prms!$D$14, IF(F32=prms!$B$15,prms!$D$15, IF(F32=prms!$B$16,prms!$D$16, IF(F32=prms!$B$17,prms!$D$17, IF(F32=prms!$B$18,prms!$D$18, IF(F32=prms!$B$19,prms!$D$19, IF(F32=prms!$B$20,prms!$D$20, IF(F32=prms!$B$21,prms!$D$21, IF(F32=prms!$B$22,prms!$D$22, IF(F32=prms!$B$23,prms!$D$23, IF(F32=prms!$B$24,prms!$D$24, IF(F32=prms!$B$25,prms!$D$25, IF(F32=prms!$B$26,prms!$D$26, IF(F32=prms!$B$27,prms!$D$27, IF(F32=prms!$B$28,prms!$D$28, IF(F32=prms!$B$29,prms!$D$29))))))))))))))))))))))))) -> 1720
B36: layer 5 width | E36: (m) | F36: 20
B37: layer 5 height | E37: (m) | F37: 0.3
B38: layer 5 type | E38: (/) | F38: rock 75% earth 25%
B39: density in bank | D39: ρb,5 | E39: (kg/m3) | F39: =IF( F38=prms!$B$5,prms!$C$5, IF(F38=prms!$B$6,prms!$C$6, IF(F38=prms!$B$7,prms!$C$7, IF(F38=prms!$B$8,prms!$C$8, IF(F38=prms!$B$9,prms!$C$9, IF(F38=prms!$B$10,prms!$C$10, IF(F38=prms!$B$11,prms!$C$11, IF(F38=prms!$B$12,prms!$C$12, IF(F38=prms!$B$13,prms!$C$13, IF(F38=prms!$B$14,prms!$C$14, IF(F38=prms!$B$15,prms!$C$15, IF(F38=prms!$B$16,prms!$C$16, IF(F38=prms!$B$17,prms!$C$17, IF(F38=prms!$B$18,prms!$C$18, IF(F38=prms!$B$19,prms!$C$19, IF(F38=prms!$B$20,prms!$C$20, IF(F38=prms!$B$21,prms!$C$21, IF(F38=prms!$B$22,prms!$C$22, IF(F38=prms!$B$23,prms!$C$23, IF(F38=prms!$B$24,prms!$C$24, IF(F38=prms!$B$25,prms!$C$25, IF(F38=prms!$B$26,prms!$C$26, IF(F38=prms!$B$27,prms!$C$27, IF(F38=prms!$B$28,prms!$C$28, IF(F38=prms!$B$29,prms!$C$29, ))))))))))))))))))))))))) -> 2790
B40: density loose | D40: ρl,5 | E40: (kg/m3) | F40: =IF( F38=prms!$B$5,prms!$D$5, IF(F38=prms!$B$6,prms!$D$6, IF(F38=prms!$B$7,prms!$D$7, IF(F38=prms!$B$8,prms!$D$8, IF(F38=prms!$B$9,prms!$D$9, IF(F38=prms!$B$10,prms!$D$10, IF(F38=prms!$B$11,prms!$D$11, IF(F38=prms!$B$12,prms!$D$12, IF(F38=prms!$B$13,prms!$D$13, IF(F38=prms!$B$14,prms!$D$14, IF(F38=prms!$B$15,prms!$D$15, IF(F38=prms!$B$16,prms!$D$16, IF(F38=prms!$B$17,prms!$D$17, IF(F38=prms!$B$18,prms!$D$18, IF(F38=prms!$B$19,prms!$D$19, IF(F38=prms!$B$20,prms!$D$20, IF(F38=prms!$B$21,prms!$D$21, IF(F38=prms!$B$22,prms!$D$22, IF(F38=prms!$B$23,prms!$D$23, IF(F38=prms!$B$24,prms!$D$24, IF(F38=prms!$B$25,prms!$D$25, IF(F38=prms!$B$26,prms!$D$26, IF(F38=prms!$B$27,prms!$D$27, IF(F38=prms!$B$28,prms!$D$28, IF(F38=prms!$B$29,prms!$D$29))))))))))))))))))))))))) -> 1960
B42: total fill volume | E42: (m3) | F42: =F4*(F12*F13+F18*F19+F24*F25+F30*F31+F36*F37) -> 30000
B44: LOADERS FOR FILLING (up to three types of loader)
B46: loader "A" | E46: (-) | F46: 1 | G46: "1" for use, "0" for no use
B47: loader "A" type | E47: (/) | F47: mini loader
B48: power | E48: (kW) | F48: 60 | G48: inside this suggested range | I48: =IF($F$47=prms!I5,prms!J5,IF($F$47=prms!I6,prms!J6,IF('2 FILL'!$F$47=prms!I7,prms!J7,IF('2 FILL'!$F$47=prms!I8,prms!J8,IF('2 FILL'!$F$47=prms!I9,prms!J9,1))))) -> 52 - 71
B49: bucket capacity | E49: (m3) | F49: 1.5 | G49: inside this suggested range | I49: =IF($F$47=prms!I5,prms!K5,IF($F$47=prms!I6,prms!K6,IF('2 FILL'!$F$47=prms!I7,prms!K7,IF('2 FILL'!$F$47=prms!I8,prms!K8,IF('2 FILL'!$F$47=prms!I9,prms!K9,1))))) -> 0.23 - 1.80
B50: specific consumption | D50: SClo,A | E50: (kg / kW h) | F50: 0.25 | G50: 0.25 if characteristic curve is not available
B51: grade of the slope | D51: Glo,A | E51: (°) | F51: 5 | G51: inside this suggested range | I51: 0 - 35
B52: specific weight of fuel | D52: ρlo,A,fuel | E52: (kg/l) | F52: 0.85
B53: productivity | D53: Prlo,A | E53: (h/m3) | F53: 0.01 | G53: inside this suggested range | I53: 0.007 - 0.012
...

Sheet 2 SBGR
B2: ROAD LENGTH
B4: road length | E4: (m) | F4: 1000
B6: SUBGRADE TERRAIN TYPE (to be compacted)
B8: width to be compacted | E8: (m) | F8: 20
B9: depth to be compacted | E9: (m) | F9: 0.3
B10: subgrade type | E10: (/) | F10: clay - dry
B11: density in bank | D11: ρb | E11: (kg/m3) | F11: =IF( F10=prms!$B$5,prms!$C$5, IF(F10=prms!$B$6,prms!$C$6, IF(F10=prms!$B$7,prms!$C$7, IF(F10=prms!$B$8,prms!$C$8, IF(F10=prms!$B$9,prms!$C$9, IF(F10=prms!$B$10,prms!$C$10, IF(F10=prms!$B$11,prms!$C$11, IF(F10=prms!$B$12,prms!$C$12, IF(F10=prms!$B$13,prms!$C$13, IF(F10=prms!$B$14,prms!$C$14, IF(F10=prms!$B$15,prms!$C$15, IF(F10=prms!$B$16,prms!$C$16, IF(F10=prms!$B$17,prms!$C$17, IF(F10=prms!$B$18,prms!$C$18, IF(F10=prms!$B$19,prms!$C$19, IF(F10=prms!$B$20,prms!$C$20, IF(F10=prms!$B$21,prms!$C$21, IF(F10=prms!$B$22,prms!$C$22, IF(F10=prms!$B$23,prms!$C$23, IF(F10=prms!$B$24,prms!$C$24, IF(F10=prms!$B$25,prms!$C$25, IF(F10=prms!$B$26,prms!$C$26, IF(F10=prms!$B$27,prms!$C$27, IF(F10=prms!$B$28,prms!$C$28, IF(F10=prms!$B$29,prms!$C$29, ))))))))))))))))))))))))) -> 1840
B12: density loose | D12: ρl | E12: (kg/m3) | F12: =IF( F10=prms!$B$5,prms!$D$5, IF(F10=prms!$B$6,prms!$D$6, IF(F10=prms!$B$7,prms!$D$7, IF(F10=prms!$B$8,prms!$D$8, IF(F10=prms!$B$9,prms!$D$9, IF(F10=prms!$B$10,prms!$D$10, IF(F10=prms!$B$11,prms!$D$11, IF(F10=prms!$B$12,prms!$D$12, IF(F10=prms!$B$13,prms!$D$13, IF(F10=prms!$B$14,prms!$D$14, IF(F10=prms!$B$15,prms!$D$15, IF(F10=prms!$B$16,prms!$D$16, IF(F10=prms!$B$17,prms!$D$17, IF(F10=prms!$B$18,prms!$D$18, IF(F10=prms!$B$19,prms!$D$19, IF(F10=prms!$B$20,prms!$D$20, IF(F10=prms!$B$21,prms!$D$21, IF(F10=prms!$B$22,prms!$D$22, IF(F10=prms!$B$23,prms!$D$23, IF(F10=prms!$B$24,prms!$D$24, IF(F10=prms!$B$25,prms!$D$25, IF(F10=prms!$B$26,prms!$D$26, IF(F10=prms!$B$27,prms!$D$27, IF(F10=prms!$B$28,prms!$D$28, IF(F10=prms!$B$29,prms!$D$29))))))))))))))))))))))))) -> 1480
B14: COMPACTOR ROLLER
B16: compactor type | E16: (/) | F16: light smooth drum roller
B17: power | E17: (kW) | F17: 75 | G17: inside this suggested range | I17: =IF($F$16=prms!$Q$5,prms!$R$5,IF($F$16=prms!Q6,prms!$R$6,IF($F$16=prms!$Q$7,prms!$R$7,IF($F$16=prms!$Q$8,prms!$R$8,IF($F$16=prms!$Q$9,prms!R$9,IF($F$16=prms!$Q$10,prms!$R$10,1)))))) -> 30 - 119
B18: compaction width | E18: (m) | F18: 1.9 | G18: inside this suggested range | I18: =IF($F$16=prms!$Q$5,prms!$S$5,IF($F$16=prms!$Q$6,prms!$S$6,IF($F$16=prms!$Q$7,prms!$S$7,IF($F$16=prms!$Q$8,prms!$S$8,IF($F$16=prms!$Q$9,prms!$S$9,IF($F$16=prms!$Q$10,prms!$S$10,1)))))) -> 1.20 - 2.20
B19: specific consumption | D19: SCcom | E19: (kg / kW h) | F19: 0.25 | G19: 0.25 if characteristic curve is not available
B20: grade of the slope | D20: Gcom | E20: (°) | F20: 5 | G20: inside this suggested range | I20: 0 - 35
B21: specific weight of fuel | D21: ρcom,fuel | E21: (kg/l) | F21: 0.85
B22: productivity | D22: Prcom | E22: (h/m3) | F22: 0.01 | G22: inside this suggested range | I22: 0.007 - 0.012
B23: load factor 1 | D23: LFcom,1 | E23: (-) | F23: =0.05173*EXP(0.00142*$F$12) -> 0.42311241
B24: load factor 2 | D24: LFcom,2 | E24: (-) | F24: =0.21032*F20^0.4321 -> 0.42160477
B25: fuel consumption per m3 | D25: FCcom,m3 | E25: (l/m3) | F25: =F17*F19*( F23 +F24 )/2*1/F21*F22 -> 0.093167335
B27: BINDING AGENT SPREADER
B29: vehicle | E29: (/) | F29: 1 | G29: "1" for use, "0" for no use
B30: vehicle type | E30: (/) | F30: agent spreader
B31: productivity | D31: Pras | E31: (m3/h) | F31: 150 | G31: inside this suggested range | I31: =IF(F30=prms!$AF$5,prms!$AG$5, 1) -> 100 - 200
B32: fuel consumption per h | D32: Ias | E32: (l/h) | F32: 2 | G32: inside this suggested range | I32: =IF(F30=prms!$AF$5,prms!$AH$5, 1) -> 1 -3
B33: thickness to be treated | E33: (m) | F33: 0.1
B34: volume to be treated | E34: (m3) | F34: =F33*$F$4*$F$8 -> 2000
B36: BINDING AGENT MIXER
B38: vehicle | E38: (/) | F38: 1 | G38: "1" for use, "0" for no use
B39: vehicle type | E39: (/) | F39: agent mixer
B40: productivity | D40: Pram | E40: (m3/h) | F40: 800 | G40: inside this suggested range | I40: =IF(F39=prms!$AJ$5,prms!$AK$5, 1) -> 700 - 900
B41: fuel consumption per h | D41: Iam | E41: (l/h) | F41: 80 | G41: inside this suggested range | I41: =IF(F39=prms!$AJ$5,prms!$AL$5, 1) -> 70 - 90
B42: thickness to be treated | E42: (m) | F42: 0.3
B43: volume to be treated | E43: (m3) | F43: =F42*$F$4*$F$8 -> 6000
B45: COMPACTOR ROLLER
B47: fuel consumption total area | E47: (l) | F47: =F25*F8*F4*F9 -> 559.00401
B48: number of compaction passages | E48: (-) | F48: 8
B50: fuel consumption | D50: FCcom | E50: (l) | F50: =F47*F48 -> 4472.0321
B51: emission factor for diesel | D51: EFdiesel | E51: (CO2/l) | F51: 2.6
B52: carbon dioxide emission | D52: CO2 | E52: (kg) | F52: =F50*F51 -> 11627.283
E53: (t) | F53: =F52/1000 -> 11.627283
...

Sheet 2 SBBS
B2: ROAD LENGTH
B4: road length | E4: (m) | F4: 1000
B6: SUBBASE TYPE
B8: subbase width | E8: (m) | F8: 18
B9: subbase thickness | E9: (m) | F9: 0.5
B10: subbase type | E10: (/) | F10: gravel - dry
B11: density in bank | D11: ρb | E11: (kg/m3) | F11: =IF( F10=prms!$B$5,prms!$C$5, IF(F10=prms!$B$6,prms!$C$6, IF(F10=prms!$B$7,prms!$C$7, IF(F10=prms!$B$8,prms!$C$8, IF(F10=prms!$B$9,prms!$C$9, IF(F10=prms!$B$10,prms!$C$10, IF(F10=prms!$B$11,prms!$C$11, IF(F10=prms!$B$12,prms!$C$12, IF(F10=prms!$B$13,prms!$C$13, IF(F10=prms!$B$14,prms!$C$14, IF(F10=prms!$B$15,prms!$C$15, IF(F10=prms!$B$16,prms!$C$16, IF(F10=prms!$B$17,prms!$C$17, IF(F10=prms!$B$18,prms!$C$18, IF(F10=prms!$B$19,prms!$C$19, IF(F10=prms!$B$20,prms!$C$20, IF(F10=prms!$B$21,prms!$C$21, IF(F10=prms!$B$22,prms!$C$22, IF(F10=prms!$B$23,prms!$C$23, IF(F10=prms!$B$24,prms!$C$24, IF(F10=prms!$B$25,prms!$C$25, IF(F10=prms!$B$26,prms!$C$26, IF(F10=prms!$B$27,prms!$C$27, IF(F10=prms!$B$28,prms!$C$28, IF(F10=prms!$B$29,prms!$C$29, ))))))))))))))))))))))))) -> 1690
B12: density loose | D12: ρl | E12: (kg/m3) | F12: =IF( F10=prms!$B$5,prms!$D$5, IF(F10=prms!$B$6,prms!$D$6, IF(F10=prms!$B$7,prms!$D$7, IF(F10=prms!$B$8,prms!$D$8, IF(F10=prms!$B$9,prms!$D$9, IF(F10=prms!$B$10,prms!$D$10, IF(F10=prms!$B$11,prms!$D$11, IF(F10=prms!$B$12,prms!$D$12, IF(F10=prms!$B$13,prms!$D$13, IF(F10=prms!$B$14,prms!$D$14, IF(F10=prms!$B$15,prms!$D$15, IF(F10=prms!$B$16,prms!$D$16, IF(F10=prms!$B$17,prms!$D$17, IF(F10=prms!$B$18,prms!$D$18, IF(F10=prms!$B$19,prms!$D$19, IF(F10=prms!$B$20,prms!$D$20, IF(F10=prms!$B$21,prms!$D$21, IF(F10=prms!$B$22,prms!$D$22, IF(F10=prms!$B$23,prms!$D$23, IF(F10=prms!$B$24,prms!$D$24, IF(F10=prms!$B$25,prms!$D$25, IF(F10=prms!$B$26,prms!$D$26, IF(F10=prms!$B$27,prms!$D$27, IF(F10=prms!$B$28,prms!$D$28, IF(F10=prms!$B$29,prms!$D$29))))))))))))))))))))))))) -> 1510
B14: total subbase volume | E14: (m3) | F14: =F4*F8*F9 -> 9000
B16: DOZER FOR SPREADING SUBBASE
B18: dozer type | E18: (/) | F18: medium dozer
B19: power | E19: (kW) | F19: 150 | G19: inside this suggested range | I19: =IF(F18=prms!$M$5,prms!$N$5, IF('2 SBBS'!F18=prms!$M$6,prms!$N$6,IF('2 SBBS'!F18=prms!$M$7,prms!$N$7,1 ))) -> 131 - 195
B20: blade width | E20: (m) | F20: 4 | G20: inside this suggested range | I20: =IF(F18=prms!$M$5,prms!$O$5, IF('2 SBBS'!F18=prms!$M$6,prms!$O$6,IF('2 SBBS'!F18=prms!$M$7,prms!$O$7,1 ))) -> 2.99 - 5.77
B21: specific consumption | D21: SCdo | E21: (kg / kW h) | F21: 0.25 | G21: 0.25 if characteristic curve is not available
B22: grade of the slope | D22: Gdo | E22: (°) | F22: 5 | G22: inside this suggested range | I22: 0 - 35
B23: specific weight of fuel | D23: ρdo,fuel | E23: (kg/l) | F23: 0.85
B24: productivity | D24: Prdo | E24: (h/m3) | F24: 0.01 | G24: inside this suggested range | I24: 0.007 - 0.012
B25: load factor 1 | D25: LFdo,1 | E25: (-) | F25: =0.05862*EXP(0.00101*$F$12) -> 0.26939425
B26: load factor 2 | D26: LFdo,2 | E26: (-) | F26: =0.00868*F22+0.15333 -> 0.19673
B27: fuel consumption per m3 | D27: FCdo,m3 | E27: (l/m3) | F27: =F19*F21*( F25+F26 )/2*1/F23*F24 -> 0.10282153
B29: COMPACTOR ROLLER
B31: compactor type | E31: (/) | F31: vibratory soil compactor
B32: power | E32: (kW) | F32: 120 | G32: inside this suggested range | I32: =IF($F$31=prms!$Q$5,prms!$R$5,IF($F$31=prms!Q6,prms!$R$6,IF($F$31=prms!$Q$7,prms!$R$7,IF($F$31=prms!$Q$8,prms!$R$8,IF($F$31=prms!$Q$9,prms!R$9,IF($F$31=prms!$Q$10,prms!$R$10,1)))))) -> 48 - 160
B33: compaction width | E33: (m) | F33: 2 | G33: inside this suggested range | I33: =IF($F$31=prms!$Q$5,prms!$S$5,IF($F$31=prms!$Q$6,prms!$S$6,IF($F$31=prms!$Q$7,prms!$S$7,IF($F$31=prms!$Q$8,prms!$S$8,IF($F$31=prms!$Q$9,prms!$S$9,IF($F$31=prms!$Q$10,prms!$S$10,1)))))) -> 1.67 - 2.14
B34: specific consumption | D34: SCcom | E34: (kg / kW h) | F34: 0.25 | G34: 0.25 if characteristic curve is not available
B35: grade of the slope | D35: Gcom | E35: (°) | F35: 5 | G35: inside this suggested range | I35: 0 - 35
B36: specific weight of fuel | D36: ρcom,fuel | E36: (kg/l) | F36: 0.85
B37: productivity | D37: Prcom | E37: (h/m3) | F37: 0.01 | G37: inside this suggested range | I37: 0.007 - 0.012
B38: load factor 1 | D38: LFcom,1 | E38: (-) | F38: =0.05173*EXP(0.00142*$F$12) -> 0.44152643
B39: load factor 2 | D39: LFcom,2 | E39: (-) | F39: =0.21032*F35^0.4321 -> 0.42160477
B40: fuel consumption per m3 | D40: FCcom,m3 | E40: (l/m3) | F40: =F32*F34*( F38 +F39 )/2*1/F36*F37 -> 0.15231727
B42: TRANSPORT TO FREIGHT SUBBASE (up to three types of vehicles)
B44: vehicle "A" | E44: (-) | F44: 1 | G44: "1" for use, "0" for no use
B45: vehicle "A" type | E45: (/) | F45: light on-road truck
B46: capacity | D46: Ctr,A | E46: (m3) | F46: 7.5 | G46: inside this suggested range | I46: =IF(F45=prms!$AA$5,prms!$AC$5, IF(F45=prms!$AA$6,prms!$AC$6, IF(F45=prms!$AA$7,prms!$AC$7, IF(F45=prms!$AA$8,prms!$AC$8,IF(F45=prms!$AA$9,prms!$AC$9,1))))) -> 5 - 10
B47: fuel consumption | D47: Itr,A | E47: (l/km) | F47: 0.15 | G47: inside this suggested range | I47: =IF(F45=prms!$AA$5,prms!$AD$5, IF(F45=prms!$AA$6,prms!$AD$6, IF(F45=prms!$AA$7,prms!$AD$7, IF(F45=prms!$AA$8,prms!$AD$8,IF(F45=prms!$AA$9,prms!$AD$9,1))))) -> 0.2 - 0.1
B48: traveling distance | D48: Rtr,A | E48: (km) | F48: 10
B49: K full-empty coefficient | D49: Ktr,A | E49: (-) | F49: 1.7
B50: fuel consumption per m3 | D50: FCtr,A,m3 | E50: (l/m3) | F50: =F49*F48*F47/F46 -> 0.34
B52: vehicle "B" | E52: (-) | F52: 1 | G52: "1" for use, "0" for no use
...

Sheet 2 BASE
B2: ROAD LENGTH
B4: road length | E4: (m) | F4: 1000
B6: BASE TYPE
B8: base width | E8: (m) | F8: 16
B9: base thickness | E9: (m) | F9: 0.3
B10: base type | E10: (/) | F10: gravel - dry 6-50 mm
B11: density in bank | D11: ρb | E11: (kg/m3) | F11: =IF( F10=prms!$B$5,prms!$C$5, IF(F10=prms!$B$6,prms!$C$6, IF(F10=prms!$B$7,prms!$C$7, IF(F10=prms!$B$8,prms!$C$8, IF(F10=prms!$B$9,prms!$C$9, IF(F10=prms!$B$10,prms!$C$10, IF(F10=prms!$B$11,prms!$C$11, IF(F10=prms!$B$12,prms!$C$12, IF(F10=prms!$B$13,prms!$C$13, IF(F10=prms!$B$14,prms!$C$14, IF(F10=prms!$B$15,prms!$C$15, IF(F10=prms!$B$16,prms!$C$16, IF(F10=prms!$B$17,prms!$C$17, IF(F10=prms!$B$18,prms!$C$18, IF(F10=prms!$B$19,prms!$C$19, IF(F10=prms!$B$20,prms!$C$20, IF(F10=prms!$B$21,prms!$C$21, IF(F10=prms!$B$22,prms!$C$22, IF(F10=prms!$B$23,prms!$C$23, IF(F10=prms!$B$24,prms!$C$24, IF(F10=prms!$B$25,prms!$C$25, IF(F10=prms!$B$26,prms!$C$26, IF(F10=prms!$B$27,prms!$C$27, IF(F10=prms!$B$28,prms!$C$28, IF(F10=prms!$B$29,prms!$C$29, ))))))))))))))))))))))))) -> 1900
B12: density loose | D12: ρl | E12: (kg/m3) | F12: =IF( F10=prms!$B$5,prms!$D$5, IF(F10=prms!$B$6,prms!$D$6, IF(F10=prms!$B$7,prms!$D$7, IF(F10=prms!$B$8,prms!$D$8, IF(F10=prms!$B$9,prms!$D$9, IF(F10=prms!$B$10,prms!$D$10, IF(F10=prms!$B$11,prms!$D$11, IF(F10=prms!$B$12,prms!$D$12, IF(F10=prms!$B$13,prms!$D$13, IF(F10=prms!$B$14,prms!$D$14, IF(F10=prms!$B$15,prms!$D$15, IF(F10=prms!$B$16,prms!$D$16, IF(F10=prms!$B$17,prms!$D$17, IF(F10=prms!$B$18,prms!$D$18, IF(F10=prms!$B$19,prms!$D$19, IF(F10=prms!$B$20,prms!$D$20, IF(F10=prms!$B$21,prms!$D$21, IF(F10=prms!$B$22,prms!$D$22, IF(F10=prms!$B$23,prms!$D$23, IF(F10=prms!$B$24,prms!$D$24, IF(F10=prms!$B$25,prms!$D$25, IF(F10=prms!$B$26,prms!$D$26, IF(F10=prms!$B$27,prms!$D$27, IF(F10=prms!$B$28,prms!$D$28, IF(F10=prms!$B$29,prms!$D$29))))))))))))))))))))))))) -> 1690
B14: total base volume | E14: (m3) | F14: =F4*F8*F9 -> 4800
B16: DOZER FOR SPREADING BASE
B18: dozer type | E18: (/) | F18: small dozer
B19: power | E19: (kW) | F19: 90 | G19: inside this suggested range | I19: =IF(F18=prms!$M$5,prms!$N$5, IF('2 BASE'!F18=prms!$M$6,prms!$N$6,IF('2 BASE'!F18=prms!$M$7,prms!$N$7,1 ))) -> 66 - 131
B20: blade width | E20: (m) | F20: 3 | G20: inside this suggested range | I20: =IF(F18=prms!$M$5,prms!$O$5, IF('2 BASE'!F18=prms!$M$6,prms!$O$6,IF('2 BASE'!F18=prms!$M$7,prms!$O$7,1 ))) -> 2.71 - 3.22
B21: specific consumption | D21: SCdo | E21: (kg / kW h) | F21: 0.25 | G21: 0.25 if characteristic curve is not available
B22: grade of the slope | D22: Gdo | E22: (°) | F22: 5 | G22: inside this suggested range | I22: 0 - 35
B23: specific weight of fuel | D23: ρdo,fuel | E23: (kg/l) | F23: 0.85
B24: productivity | D24: Prdo | E24: (h/m3) | F24: 0.01 | G24: inside this suggested range | I24: 0.007 - 0.012
B25: load factor 1 | D25: LFdo,1 | E25: (-) | F25: =0.05862*EXP(0.00101*$F$12) -> 0.32310454
B26: load factor 2 | D26: LFdo,2 | E26: (-) | F26: =0.00868*F22+0.15333 -> 0.19673
B27: fuel consumption per m3 | D27: FCdo,m3 | E27: (l/m3) | F27: =F19*F21*( F25+F26 )/2*1/F23*F24 -> 0.068801631
B29: COMPACTOR ROLLER
B31: compactor type | E31: (/) | F31: light smooth drum roller
B32: power | E32: (kW) | F32: 70 | G32: inside this suggested range | I32: =IF($F$31=prms!$Q$5,prms!$R$5,IF($F$31=prms!Q6,prms!$R$6,IF($F$31=prms!$Q$7,prms!$R$7,IF($F$31=prms!$Q$8,prms!$R$8,IF($F$31=prms!$Q$9,prms!R$9,IF($F$31=prms!$Q$10,prms!$R$10,1)))))) -> 30 - 119
B33: compaction width | E33: (m) | F33: 1.8 | G33: inside this suggested range | I33: =IF($F$31=prms!$Q$5,prms!$S$5,IF($F$31=prms!$Q$6,prms!$S$6,IF($F$31=prms!$Q$7,prms!$S$7,IF($F$31=prms!$Q$8,prms!$S$8,IF($F$31=prms!$Q$9,prms!$S$9,IF($F$31=prms!$Q$10,prms!$S$10,1)))))) -> 1.20 - 2.20
B34: specific consumption | D34: SCcom | E34: (kg / kW h) | F34: 0.25 | G34: 0.25 if characteristic curve is not available
B35: grade of the slope | D35: Gcom | E35: (°) | F35: 5 | G35: inside this suggested range | I35: 0 - 35
B36: specific weight of fuel | D36: ρcom,fuel | E36: (kg/l) | F36: 0.85
B37: productivity | D37: Prcom | E37: (h/m3) | F37: 0.01 | G37: inside this suggested range | I37: 0.007 - 0.012
B38: load factor 1 | D38: LFcom,1 | E38: (-) | F38: =0.05173*EXP(0.00142*$F$12) -> 0.57011488
B39: load factor 2 | D39: LFcom,2 | E39: (-) | F39: =0.21032*F35^0.4321 -> 0.42160477
B40: fuel consumption per m3 | D40: FCcom,m3 | E40: (l/m3) | F40: =F32*F34*( F38 +F39 )/2*1/F36*F37 -> 0.10208879
B42: TRANSPORT TO FREIGHT BASE (up to three types of vehicles)
B44: vehicle "A" | E44: (-) | F44: 1 | G44: "1" for use, "0" for no use
B45: vehicle "A" type | E45: (/) | F45: light on-road truck
B46: capacity | D46: Ctr,A | E46: (m3) | F46: 7.5 | G46: inside this suggested range | I46: =IF(F45=prms!$AA$5,prms!$AC$5, IF(F45=prms!$AA$6,prms!$AC$6, IF(F45=prms!$AA$7,prms!$AC$7, IF(F45=prms!$AA$8,prms!$AC$8,IF(F45=prms!$AA$9,prms!$AC$9,1))))) -> 5 - 10
B47: fuel consumption | D47: Itr,A | E47: (l/km) | F47: 0.15 | G47: inside this suggested range | I47: =IF(F45=prms!$AA$5,prms!$AD$5, IF(F45=prms!$AA$6,prms!$AD$6, IF(F45=prms!$AA$7,prms!$AD$7, IF(F45=prms!$AA$8,prms!$AD$8,IF(F45=prms!$AA$9,prms!$AD$9,1))))) -> 0.2 - 0.1
B48: traveling distance | D48: Rtr,A | E48: (km) | F48: 10
B49: K full-empty coefficient | D49: Ktr,A | E49: (-) | F49: 1.7
B50: fuel consumption per m3 | D50: FCtr,A,m3 | E50: (l/m3) | F50: =F49*F48*F47/F46 -> 0.34
B52: vehicle "B" | E52: (-) | F52: 1 | G52: "1" for use, "0" for no use
...

Sheet 2 BIND
B2: ROAD LENGTH
B4: road length | E4: (m) | F4: 1000
B6: BINDER LAYER TYPE
B8: binder layer width | E8: (m) | F8: 16
B9: binder layer thickness | E9: (m) | F9: 0.05
B10: binder layer type | E10: (/) | F10: asphalt concrete | G10: choose "asphalt concrete"
B11: density in bank | D11: ρb | E11: (kg/m3) | F11: =IF( F10=prms!$B$5,prms!$C$5, IF(F10=prms!$B$6,prms!$C$6, IF(F10=prms!$B$7,prms!$C$7, IF(F10=prms!$B$8,prms!$C$8, IF(F10=prms!$B$9,prms!$C$9, IF(F10=prms!$B$10,prms!$C$10, IF(F10=prms!$B$11,prms!$C$11, IF(F10=prms!$B$12,prms!$C$12, IF(F10=prms!$B$13,prms!$C$13, IF(F10=prms!$B$14,prms!$C$14, IF(F10=prms!$B$15,prms!$C$15, IF(F10=prms!$B$16,prms!$C$16, IF(F10=prms!$B$17,prms!$C$17, IF(F10=prms!$B$18,prms!$C$18, IF(F10=prms!$B$19,prms!$C$19, IF(F10=prms!$B$20,prms!$C$20, IF(F10=prms!$B$21,prms!$C$21, IF(F10=prms!$B$22,prms!$C$22, IF(F10=prms!$B$23,prms!$C$23, IF(F10=prms!$B$24,prms!$C$24, IF(F10=prms!$B$25,prms!$C$25, IF(F10=prms!$B$26,prms!$C$26, IF(F10=prms!$B$27,prms!$C$27, IF(F10=prms!$B$28,prms!$C$28, IF(F10=prms!$B$29,prms!$C$29, ))))))))))))))))))))))))) -> 2200
B12: density loose | D12: ρl | E12: (kg/m3) | F12: =IF( F10=prms!$B$5,prms!$D$5, IF(F10=prms!$B$6,prms!$D$6, IF(F10=prms!$B$7,prms!$D$7, IF(F10=prms!$B$8,prms!$D$8, IF(F10=prms!$B$9,prms!$D$9, IF(F10=prms!$B$10,prms!$D$10, IF(F10=prms!$B$11,prms!$D$11, IF(F10=prms!$B$12,prms!$D$12, IF(F10=prms!$B$13,prms!$D$13, IF(F10=prms!$B$14,prms!$D$14, IF(F10=prms!$B$15,prms!$D$15, IF(F10=prms!$B$16,prms!$D$16, IF(F10=prms!$B$17,prms!$D$17, IF(F10=prms!$B$18,prms!$D$18, IF(F10=prms!$B$19,prms!$D$19, IF(F10=prms!$B$20,prms!$D$20, IF(F10=prms!$B$21,prms!$D$21, IF(F10=prms!$B$22,prms!$D$22, IF(F10=prms!$B$23,prms!$D$23, IF(F10=prms!$B$24,prms!$D$24, IF(F10=prms!$B$25,prms!$D$25, IF(F10=prms!$B$26,prms!$D$26, IF(F10=prms!$B$27,prms!$D$27, IF(F10=prms!$B$28,prms!$D$28, IF(F10=prms!$B$29,prms!$D$29))))))))))))))))))))))))) -> /
B14: total binder layer volume | E14: (m3) | F14: =F4*F8*F9 -> 800
B16: ASPHALT PAVER
B18: asphalt paver type | E18: (/) | F18: small asphalt paver
B19: power | E19: (kW) | F19: 40 | G19: inside this suggested range | I19: =IF(F18=prms!$V$5,prms!$W$5, IF('2 BIND'!F18=prms!$V$6,prms!$W$6,IF('2 BIND'!F18=prms!$V$7,prms!$W$7,1 ))) -> 34 - 55
B20: operating capacity | E20: (m3) | F20: 3.5 | G20: inside this suggested range | I20: =IF(F18=prms!$V$5,prms!$Y$5, IF('2 BIND'!F18=prms!$V$6,prms!$Y$6,IF('2 BIND'!F18=prms!$V$7,prms!$Y$7,1 ))) -> 3 - 4
B21: specific consumption | D21: SCap | E21: (kg / kW h) | F21: 0.25 | G21: 0.25 if characteristic curve is not available
B22: grade of the slope | D22: Gap | E22: (°) | F22: 2 | G22: inside this suggested range | I22: 0 - 35
B23: specific weight of fuel | D23: ρap,fuel | E23: (kg/l) | F23: 0.85
B24: productivity | D24: Prap | E24: (h/m3) | F24: 0.01 | G24: inside this suggested range | I24: 0.007 - 0.012
B25: load factor 1 | D25: LFap,1 | E25: (-) | F25: =0.05862*EXP(0.00101*$F$11) -> 0.54081428
B26: load factor 2 | D26: LFap,2 | E26: (-) | F26: =0.00868*F22+0.15333 -> 0.17069
B27: fuel consumption per m3 | D27: FCap,m3 | E27: (l/m3) | F27: =F19*F21*( F25+F26 )/2*1/F23*F24 -> 0.041853193
B29: COMPACTOR ROLLER
B31: compactor type | E31: (/) | F31: tandem vibratory roller
B32: power | E32: (kW) | F32: 70 | G32: inside this suggested range | I32: =IF($F$31=prms!$Q$5,prms!$R$5,IF($F$31=prms!Q6,prms!$R$6,IF($F$31=prms!$Q$7,prms!$R$7,IF($F$31=prms!$Q$8,prms!$R$8,IF($F$31=prms!$Q$9,prms!R$9,IF($F$31=prms!$Q$10,prms!$R$10,1)))))) -> 51 - 100
B33: compaction width | E33: (m) | F33: 1.8 | G33: inside this suggested range | I33: =IF($F$31=prms!$Q$5,prms!$S$5,IF($F$31=prms!$Q$6,prms!$S$6,IF($F$31=prms!$Q$7,prms!$S$7,IF($F$31=prms!$Q$8,prms!$S$8,IF($F$31=prms!$Q$9,prms!$S$9,IF($F$31=prms!$Q$10,prms!$S$10,1)))))) -> 1.13 - 2.13
B34: specific consumption | D34: SCcom | E34: (kg / kW h) | F34: 0.25 | G34: 0.25 if characteristic curve is not available
B35: grade of the slope | D35: Gcom | E35: (°) | F35: 2 | G35: inside this suggested range | I35: 0 - 35
B36: specific weight of fuel | D36: ρcom,fuel | E36: (kg/l) | F36: 0.85
B37: productivity | D37: Prcom | E37: (h/m3) | F37: 0.01 | G37: inside this suggested range | I37: 0.007 - 0.012
B38: load factor 1 | D38: LFcom,1 | E38: (-) | F38: =0.05173*EXP(0.00142*$F$11) -> 1.1761926
B39: load factor 2 | D39: LFcom,2 | E39: (-) | F39: =0.21032*F35^0.4321 -> 0.28376291
B40: fuel consumption per m3 | D40: FCcom,m3 | E40: (l/m3) | F40: =F32*F34*( F38 +F39 )/2*1/F36*F37 -> 0.15028954
B42: TACK COAT AGENT SPREADER
B44: vehicle | E44: (-) | F44: 1 | G44: "1" for use, "0" for no use
B45: vehicle type | E45: (/) | F45: agent spreader
B46: productivity | D46: Pras | E46: (m3/h) | F46: 150 | G46: inside this suggested range | I46: =IF(F45=prms!$AF$5,prms!$AG$5, 1) -> 100 - 200
B47: fuel consumption | D47: Ias | E47: (l/h) | F47: 2 | G47: inside this suggested range | I47: =IF(F45=prms!$AF$5,prms!$AH$5, 1) -> 1 -3
B48: thickness to be treated | E48: (m) | F48: 0.005
B49: volume to be treated | E49: (m3) | F49: =F48*$F$4*$F$8 -> 80
B51: TRANSPORT TO FREIGHT ASPHALT CONCRETE (up to three types of vehicles)
B53: vehicle "A" | E53: (-) | F53: 1 | G53: "1" for use, "0" for no use
...

Sheet 2 WEAR
B2: ROAD LENGTH
B4: road length | E4: (m) | F4: 1000
B6: WEARING LAYER TYPE
B8: wearing layer width | E8: (m) | F8: 16
B9: wearing layer thickness | E9: (m) | F9: 0.04
B10: binder layer type | E10: (/) | F10: asphalt concrete | G10: choose "asphalt concrete"
B11: density in bank | D11: ρb | E11: (kg/m3) | F11: =IF( F10=prms!$B$5,prms!$C$5, IF(F10=prms!$B$6,prms!$C$6, IF(F10=prms!$B$7,prms!$C$7, IF(F10=prms!$B$8,prms!$C$8, IF(F10=prms!$B$9,prms!$C$9, IF(F10=prms!$B$10,prms!$C$10, IF(F10=prms!$B$11,prms!$C$11, IF(F10=prms!$B$12,prms!$C$12, IF(F10=prms!$B$13,prms!$C$13, IF(F10=prms!$B$14,prms!$C$14, IF(F10=prms!$B$15,prms!$C$15, IF(F10=prms!$B$16,prms!$C$16, IF(F10=prms!$B$17,prms!$C$17, IF(F10=prms!$B$18,prms!$C$18, IF(F10=prms!$B$19,prms!$C$19, IF(F10=prms!$B$20,prms!$C$20, IF(F10=prms!$B$21,prms!$C$21, IF(F10=prms!$B$22,prms!$C$22, IF(F10=prms!$B$23,prms!$C$23, IF(F10=prms!$B$24,prms!$C$24, IF(F10=prms!$B$25,prms!$C$25, IF(F10=prms!$B$26,prms!$C$26, IF(F10=prms!$B$27,prms!$C$27, IF(F10=prms!$B$28,prms!$C$28, IF(F10=prms!$B$29,prms!$C$29, ))))))))))))))))))))))))) -> 2200
B12: density loose | D12: ρl | E12: (kg/m3) | F12: =IF( F10=prms!$B$5,prms!$D$5, IF(F10=prms!$B$6,prms!$D$6, IF(F10=prms!$B$7,prms!$D$7, IF(F10=prms!$B$8,prms!$D$8, IF(F10=prms!$B$9,prms!$D$9, IF(F10=prms!$B$10,prms!$D$10, IF(F10=prms!$B$11,prms!$D$11, IF(F10=prms!$B$12,prms!$D$12, IF(F10=prms!$B$13,prms!$D$13, IF(F10=prms!$B$14,prms!$D$14, IF(F10=prms!$B$15,prms!$D$15, IF(F10=prms!$B$16,prms!$D$16, IF(F10=prms!$B$17,prms!$D$17, IF(F10=prms!$B$18,prms!$D$18, IF(F10=prms!$B$19,prms!$D$19, IF(F10=prms!$B$20,prms!$D$20, IF(F10=prms!$B$21,prms!$D$21, IF(F10=prms!$B$22,prms!$D$22, IF(F10=prms!$B$23,prms!$D$23, IF(F10=prms!$B$24,prms!$D$24, IF(F10=prms!$B$25,prms!$D$25, IF(F10=prms!$B$26,prms!$D$26, IF(F10=prms!$B$27,prms!$D$27, IF(F10=prms!$B$28,prms!$D$28, IF(F10=prms!$B$29,prms!$D$29))))))))))))))))))))))))) -> /
B14: total wearing layer volume | E14: (m3) | F14: =F4*F8*F9 -> 640
B16: ASPHALT PAVER
B18: asphalt paver type | E18: (/) | F18: small asphalt paver
B19: power | E19: (kW) | F19: 40 | G19: inside this suggested range | I19: =IF(F18=prms!$V$5,prms!$W$5, IF('2 WEAR'!F18=prms!$V$6,prms!$W$6,IF('2 WEAR'!F18=prms!$V$7,prms!$W$7,1 ))) -> 34 - 55
B20: operating capacity | E20: (m3) | F20: 3.5 | G20: inside this suggested range | I20: =IF(F18=prms!$V$5,prms!$Y$5, IF('2 WEAR'!F18=prms!$V$6,prms!$Y$6,IF('2 WEAR'!F18=prms!$V$7,prms!$Y$7,1 ))) -> 3 - 4
B21: specific consumption | D21: SCap | E21: (kg / kW h) | F21: 0.25 | G21: 0.25 if characteristic curve is not available
B22: grade of the slope | D22: Gap | E22: (°) | F22: 2 | G22: inside this suggested range | I22: 0 - 35
B23: specific weight of fuel | D23: ρap,fuel | E23: (kg/l) | F23: 0.85
B24: productivity | D24: Prap | E24: (h/m3) | F24: 0.01 | G24: inside this suggested range | I24: 0.007 - 0.012
B25: load factor 1 | D25: LFap,1 | E25: (-) | F25: =0.05862*EXP(0.00101*$F$11) -> 0.54081428
B26: load factor 2 | D26: LFap,2 | E26: (-) | F26: =0.00868*F22+0.15333 -> 0.17069
B27: fuel consumption per m3 | D27: FCap,m3 | E27: (l/m3) | F27: =F19*F21*( F25+F26 )/2*1/F23*F24 -> 0.041853193
B29: COMPACTOR ROLLER
B31: compactor type | E31: (/) | F31: tandem vibratory roller
B32: power | E32: (kW) | F32: 70 | G32: inside this suggested range | I32: =IF($F$31=prms!$Q$5,prms!$R$5,IF($F$31=prms!Q6,prms!$R$6,IF($F$31=prms!$Q$7,prms!$R$7,IF($F$31=prms!$Q$8,prms!$R$8,IF($F$31=prms!$Q$9,prms!R$9,IF($F$31=prms!$Q$10,prms!$R$10,1)))))) -> 51 - 100
B33: compaction width | E33: (m) | F33: 1.8 | G33: inside this suggested range | I33: =IF($F$31=prms!$Q$5,prms!$S$5,IF($F$31=prms!$Q$6,prms!$S$6,IF($F$31=prms!$Q$7,prms!$S$7,IF($F$31=prms!$Q$8,prms!$S$8,IF($F$31=prms!$Q$9,prms!$S$9,IF($F$31=prms!$Q$10,prms!$S$10,1)))))) -> 1.13 - 2.13
B34: specific consumption | D34: SCcom | E34: (kg / kW h) | F34: 0.25 | G34: 0.25 if characteristic curve is not available
B35: grade of the slope | D35: Gcom | E35: (°) | F35: 2 | G35: inside this suggested range | I35: 0 - 35
B36: specific weight of fuel | D36: ρcom,fuel | E36: (kg/l) | F36: 0.85
B37: productivity | D37: Prcom | E37: (h/m3) | F37: 0.01 | G37: inside this suggested range | I37: 0.007 - 0.012
B38: load factor 1 | D38: LFcom,1 | E38: (-) | F38: =0.05173*EXP(0.00142*$F$11) -> 1.1761926
B39: load factor 2 | D39: LFcom,2 | E39: (-) | F39: =0.21032*F35^0.4321 -> 0.28376291
B40: fuel consumption per m3 | D40: FCcom,m3 | E40: (l/m3) | F40: =F32*F34*( F38 +F39 )/2*1/F36*F37 -> 0.15028954
B42: SEAL COAT AGENT SPREADER
B44: vehicle | E44: (-) | F44: 1 | G44: "1" for use, "0" for no use
B45: vehicle type | E45: (/) | F45: agent spreader
B46: productivity | D46: Pras | E46: (m3/h) | F46: 150 | G46: inside this suggested range | I46: =IF(F45=prms!$AF$5,prms!$AG$5, 1) -> 100 - 200
B47: fuel consumption | D47: Ias | E47: (l/h) | F47: 2 | G47: inside this suggested range | I47: =IF(F45=prms!$AF$5,prms!$AH$5, 1) -> 1 -3
B48: thickness to be treated | E48: (m) | F48: 0.005
B49: volume to be treated | E49: (m3) | F49: =F48*$F$4*$F$8 -> 80
B51: TRANSPORT TO FREIGHT ASPHALT CONCRETE (up to three types of vehicles)
B53: vehicle "A" | E53: (-) | F53: 1 | G53: "1" for use, "0" for no use
...

Sheet 3 ROLL
B2: ROAD LENGTH
B4: road length | E4: (m) | F4: 1000
B5: road life | D5: t | E5: (year) | F5: 50
B7: TRAFFIC INFORMATION
B9: number of directions | E9: (-) | F9: 2
B11: yearly heavy vehicles per direction | E11: (-) | F11: =1000*365 -> 365000 | G11: diesel
B12: yearly grow rate | D12: phv | E12: (-) | F12: 0.01
B14: yearly light vehicles per direction | E14: (-) | F14: =20000*365 -> 7300000 | G14: diesel
B15: yearly grow rate | D15: plv | E15: (-) | F15: 0.01
B17: yearly light vehicles per direction | E17: (-) | F17: =3*365 -> 1095 | G17: diesel hybrid
B18: yearly grow rate | D18: plv,hy | E18: (-) | F18: 0.01
B20: yearly light vehicles per direction | E20: (-) | F20: =2*365 -> 730 | G20: electric
B21: yearly grow rate | D21: plv,el | E21: (-) | F21: 0.01
B23: heavy vehicle type | E23: (-) | F23: medium on-road truck | G23: diesel
B24: fuel consumption | D24: Ihv | E24: (l/km) | F24: 0.25 | G24: inside this suggested range | I24: =IF(F23=prms!$AA$5,prms!$AD$5, IF(F23=prms!$AA$6,prms!$AD$6, IF(F23=prms!$AA$7,prms!$AD$7, IF(F23=prms!$AA$8,prms!$AD$8,IF(F23=prms!$AA$9,prms!$AD$9,1))))) -> 0.3 - 0.2
B26: light vehicle type | E26: (-) | F26: car | G26: diesel
B27: fuel consumption | D27: Ilv | E27: (l/km) | F27: 0.06
B29: light vehicle type, hybrid | E29: (-) | F29: car | G29: diesel hybrid
B30: fuel consumption | D30: Ilv,hy | E30: (l/km) | F30: 0.04
B32: light vehicle type, electric | E32: (-) | F32: car | G32: electric
B33: fuel consumption | D33: Ilv,el | E33: (l/km) | F33: 0
B35: MAINTENANCE INFORMATION
B37: initial IRI | D37: IRIin | E37: (m/km) | F37: 2
B38: yearly increase in IRI | D38: Δ IRIin | E38: (m/km) | F38: 0.1
B39: maximum accepted IRI | D39: IRIfin | E39: (m/km) | F39: 4
B40: years between maint. | E40: (-) | F40: =(F39-F37)/F38 -> 20
B41: rounded years between maint. | E41: (-) | F41: =ROUND(F40,0) -> 20
B42: no. of maint. operations in life | E42: (-) | F42: =F5/F41 -> 2.5
B43: rounded no. of maint. operations in life | E43: (-) | F43: =ROUNDDOWN(F42,0) -> 2
B44: last maint. operation time span | E44: (-) | F44: =F5-F43*F41 -> 10
B46: EMISSIONS
B48: emission factor for diesel, heavy vehicles | D48: EFdiesel, hv | E48: (CO2/l) | F48: 2.6
B49: emission factor for diesel, light vehicles | D49: EFdiesel, lv | E49: (CO2/l) | F49: 2.6
B50: emission factor for electricity, light vehicles | D50: EFelectric, lv | E50: (CO2/l) | F50: 0
B52: carbon dioxide emission, heavy vehicles | D52: CO2, hv | E52: (kg) | F52: =SUM(roll!L5:L54) -> 7.2797249e+08
B53: carbon dioxide emission, light vehicles | D53: CO2, lv | E53: (kg) | F53: =SUM(roll!P5:P54) -> 4.1471345e+09
B54: carbon dioxide emission, light vehicles, hybrid | D54: CO2, hy | E54: (kg) | F54: =SUM(roll!T5:T54) -> 414713.45
B55: carbon dioxide emission, light vehicles, electric | D55: CO2, el | E55: (kg) | F55: =SUM(roll!X5:X54) -> 0
B57: total carbon dioxide emission | D57: CO2 | E57: (kg) | F57: =SUM(F52:F55) -> 4.8755217e+09
E58: (t) | F58: =F57/1000 -> 4875521.7

Sheet 3 MNTN
B2: ROAD LENGTH
B4: road length | E4: (m) | F4: 1000
B6: MAINTENANCE INFORMATION
B8: no. of maint. operations in life | E8: (-) | F8: =ROUNDUP('3 ROLL'!F42,0) -> 3
B10: TOP (WEARING+BINDER) LAYER TYPE
B12: top layer to replace width | E12: (m) | F12: 16
B13: top layer to replace thickness | E13: (m) | F13: 0.1
B14: binder layer type | E14: (-) | F14: asphalt concrete | G14: choose "asphalt concrete"
B15: density in bank | D15: ρb | E15: (kg/m3) | F15: =IF( F14=prms!$B$5,prms!$C$5, IF(F14=prms!$B$6,prms!$C$6, IF(F14=prms!$B$7,prms!$C$7, IF(F14=prms!$B$8,prms!$C$8, IF(F14=prms!$B$9,prms!$C$9, IF(F14=prms!$B$10,prms!$C$10, IF(F14=prms!$B$11,prms!$C$11, IF(F14=prms!$B$12,prms!$C$12, IF(F14=prms!$B$13,prms!$C$13, IF(F14=prms!$B$14,prms!$C$14, IF(F14=prms!$B$15,prms!$C$15, IF(F14=prms!$B$16,prms!$C$16, IF(F14=prms!$B$17,prms!$C$17, IF(F14=prms!$B$18,prms!$C$18, IF(F14=prms!$B$19,prms!$C$19, IF(F14=prms!$B$20,prms!$C$20, IF(F14=prms!$B$21,prms!$C$21, IF(F14=prms!$B$22,prms!$C$22, IF(F14=prms!$B$23,prms!$C$23, IF(F14=prms!$B$24,prms!$C$24, IF(F14=prms!$B$25,prms!$C$25, IF(F14=prms!$B$26,prms!$C$26, IF(F14=prms!$B$27,prms!$C$27, IF(F14=prms!$B$28,prms!$C$28, IF(F14=prms!$B$29,prms!$C$29, ))))))))))))))))))))))))) -> 2200
B16: density loose | D16: ρl | E16: (kg/m3) | F16: =IF( F14=prms!$B$5,prms!$D$5, IF(F14=prms!$B$6,prms!$D$6, IF(F14=prms!$B$7,prms!$D$7, IF(F14=prms!$B$8,prms!$D$8, IF(F14=prms!$B$9,prms!$D$9, IF(F14=prms!$B$10,prms!$D$10, IF(F14=prms!$B$11,prms!$D$11, IF(F14=prms!$B$12,prms!$D$12, IF(F14=prms!$B$13,prms!$D$13, IF(F14=prms!$B$14,prms!$D$14, IF(F14=prms!$B$15,prms!$D$15, IF(F14=prms!$B$16,prms!$D$16, IF(F14=prms!$B$17,prms!$D$17, IF(F14=prms!$B$18,prms!$D$18, IF(F14=prms!$B$19,prms!$D$19, IF(F14=prms!$B$20,prms!$D$20, IF(F14=prms!$B$21,prms!$D$21, IF(F14=prms!$B$22,prms!$D$22, IF(F14=prms!$B$23,prms!$D$23, IF(F14=prms!$B$24,prms!$D$24, IF(F14=prms!$B$25,prms!$D$25, IF(F14=prms!$B$26,prms!$D$26, IF(F14=prms!$B$27,prms!$D$27, IF(F14=prms!$B$28,prms!$D$28, IF(F14=prms!$B$29,prms!$D$29))))))))))))))))))))))))) -> /
B18: total top layer volume | E18: (m3) | F18: =F4*F12*F13 -> 1600
B20: MILLING MACHINE
B22: vehicle type | E22: (/) | F22: milling machine
B23: productivity | D23: Prmm | E23: (m3/h) | F23: 1250 | G23: inside this suggested range | I23: =IF(F22=prms!$AN$5,prms!$AO$5, 1) -> 1000 - 1500
B24: fuel consumption | D24: Imm | E24: (l/h) | F24: 40 | G24: inside this suggested range | I24: =IF(F22=prms!$AN$5,prms!$AP$5, 1) -> 30 - 50
B25: volume to be treated | E25: (m3) | F25: =F13*$F$4*$F$12 -> 1600
B27: ASPHALT PAVER
B29: asphalt paver type | E29: (/) | F29: small asphalt paver
B30: power | E30: (kW) | F30: 40 | G30: inside this suggested range | I30: =IF(F29=prms!$V$5,prms!$W$5, IF('3 MNTN'!F29=prms!$V$6,prms!$W$6,IF('3 MNTN'!F29=prms!$V$7,prms!$W$7,1 ))) -> 34 - 55
B31: operating capacity | E31: (m3) | F31: 3.5 | G31: inside this suggested range | I31: =IF(F29=prms!$V$5,prms!$Y$5, IF('3 MNTN'!F29=prms!$V$6,prms!$Y$6,IF('3 MNTN'!F29=prms!$V$7,prms!$Y$7,1 ))) -> 3 - 4
B32: specific consumption | D32: SCap | E32: (kg / kW h) | F32: 0.25 | G32: 0.25 if characteristic curve is not available
B33: grade of the slope | D33: Gap | E33: (°) | F33: 2 | G33: inside this suggested range | I33: 0 - 35
B34: specific weight of fuel | D34: ρap,fuel | E34: (kg/l) | F34: 0.85
B35: productivity | D35: Prap | E35: (h/m3) | F35: 0.01 | G35: inside this suggested range | I35: 0.007 - 0.012
B36: load factor 1 | D36: LFap,1 | E36: (-) | F36: =0.05862*EXP(0.00101*$F$15) -> 0.54081428
B37: load factor 2 | D37: LFap,2 | E37: (-) | F37: =0.00868*F33+0.15333 -> 0.17069
B38: fuel consumption per m3 | D38: FCap,m3 | E38: (l/m3) | F38: =F30*F32*( F36+F37 )/2*1/F34*F35 -> 0.041853193
B40: COMPACTOR ROLLER
B42: compactor type | E42: (/) | F42: tandem vibratory roller
B43: power | E43: (kW) | F43: 70 | G43: inside this suggested range | I43: =IF($F$42=prms!$Q$5,prms!$R$5,IF($F$42=prms!Q6,prms!$R$6,IF($F$42=prms!$Q$7,prms!$R$7,IF($F$42=prms!$Q$8,prms!$R$8,IF($F$42=prms!$Q$9,prms!R$9,IF($F$42=prms!$Q$10,prms!$R$10,1)))))) -> 51 - 100
B44: compaction width | E44: (m) | F44: 1.8 | G44: inside this suggested range | I44: =IF($F$42=prms!$Q$5,prms!$S$5,IF($F$42=prms!$Q$6,prms!$S$6,IF($F$42=prms!$Q$7,prms!$S$7,IF($F$42=prms!$Q$8,prms!$S$8,IF($F$42=prms!$Q$9,prms!$S$9,IF($F$42=prms!$Q$10,prms!$S$10,1)))))) -> 1.13 - 2.13
B45: specific consumption | D45: SCcom | E45: (kg / kW h) | F45: 0.25 | G45: 0.25 if characteristic curve is not available
B46: grade of the slope | D46: Gcom | E46: (°) | F46: 2 | G46: inside this suggested range | I46: 0 - 35
B47: specific weight of fuel | D47: ρcom,fuel | E47: (kg/l) | F47: 0.85
B48: productivity | D48: Prcom | E48: (h/m3) | F48: 0.01 | G48: inside this suggested range | I48: 0.007 - 0.012
B49: load factor 1 | D49: LFcom,1 | E49: (-) | F49: =0.05173*EXP(0.00142*$F$15) -> 1.1761926
B50: load factor 2 | D50: LFcom,2 | E50: (-) | F50: =0.21032*F46^0.4321 -> 0.28376291
B51: fuel consumption per m3 | D51: FCcom,m3 | E51: (l/m3) | F51: =F43*F45*( F49 +F50 )/2*1/F47*F48 -> 0.15028954
B53: SEAL COAT AGENT SPREADER
B55: vehicle | E55: (-) | F55: 1 | G55: "1" for use, "0" for no use
...

Sheet 3 ALB
B2: ROAD LENGTH
B4: road length | E4: (m) | F4: 1000
B5: road life | D5: t | E5: (year) | F5: 50
B7: TOP LAYER INFORMATION
B9: top layer width | E9: (m) | F9: 16
B10: top layer type | E10: (-) | F10: asphalt concrete | G10: choose "asphalt concrete"
B11: road surface area | D11: A | E11: (m2) | F11: =F4*F9 -> 16000
B13: albedo road surface | D13: αroad | E13: (-) | F13: 0.15
B14: mean albedo earth system | D14: αearth | E14: (-) | F14: 0.36
B15: difference in albedo | D15: Δα | E15: (-) | F15: =F14-F13 -> 0.21 | G15: positive Δ increases CO2 emission, negative Δ decreases CO2 emission
B16: change in radiative force per 0.01α variation | D16: ΔRF | E16: (-) | F16: 1.54
B17: radiative force | D17: RF | E17: (W/m2) | F17: =F16*F15/0.01 -> 32.34
B19: EMISSIONS
B21: total carbon dioxide emission | D21: CO2 | E21: (kg) | F21: =F15/0.01*1.087*F17*F5*F11/(0.217*F5 - 44.78*EXP((-F5)/172.9) - 6.26*EXP((-F5)/18.51) - 0.22*EXP((-F5)/1.186) +51.26 ) -> 20975854
E22: (t) | F22: =F21/1000 -> 20975.854

Sheet 3 LGT
B2: ROAD LENGTH
B4: road length | E4: (m) | F4: 1000
B5: road life | D5: t | E5: (year) | F5: 50
B7: LIGHTING INFORMATION
B9: lighting type | E9: (-) | F9: LED 180 W
B10: hourly carbon dioxide emission | D10: CO2 | E10: (kg/h) | F10: =IF('3 LGT'!F9=prms!AV5,prms!AX5,prms!AX6) -> 0.040833333
B11: daily no. working hours | E11: (h) | F11: 12
B12: life span working hours | E12: (h) | F12: =365*F11*F5 -> 219000
